2023-09-20 15:59:20.844 | ERROR    | __main__:screen_shot:1150 - An error has been caught in function 'screen_shot', process 'MainProcess' (13152), thread 'MainThread' (9940):
Traceback (most recent call last):

  File "C:\pycharm\pythonProject\ComparsionProject\BasicDemo\tktest.py", line 1227, in <module>
    window.mainloop()
    │      └ <function Misc.mainloop at 0x000001EE11F1F940>
    └ <tkinter.Tk object .>

  File "C:\python3.9.10\lib\tkinter\__init__.py", line 1429, in mainloop
    self.tk.mainloop(n)
    │    │  │        └ 0
    │    │  └ <method 'mainloop' of '_tkinter.tkapp' objects>
    │    └ <_tkinter.tkapp object at 0x000001EE2EA35D30>
    └ <tkinter.Tk object .>

  File "C:\python3.9.10\lib\tkinter\__init__.py", line 1892, in __call__
    return self.func(*args)
           │    │     └ ()
           │    └ <function screen_shot at 0x000001EE31AF6790>
           └ <tkinter.CallWrapper object at 0x000001EE31AF5A60>

> File "C:\pycharm\pythonProject\ComparsionProject\BasicDemo\tktest.py", line 1150, in screen_shot
    cv2.waitKey(0)
    │   └ <built-in function waitKey>
    └ <module 'cv2' from 'C:\\pycharm\\pythonProject\\ComparsionProject\\venv\\lib\\site-packages\\cv2\\__init__.py'>

  File "C:\pycharm\pythonProject\ComparsionProject\BasicDemo\tktest.py", line 1136, in on_mouse
    cv2.imshow('image', screen_img[cut_Pos[1][0]:cut_Pos[1][1], cut_Pos[0][0]:cut_Pos[0][1]])
    │   │               │          │             │              │             └ array([[  2,   2],
    │   │               │          │             │              │                      [631, 631]])
    │   │               │          │             │              └ array([[  2,   2],
    │   │               │          │             │                       [631, 631]])
    │   │               │          │             └ array([[  2,   2],
    │   │               │          │                      [631, 631]])
    │   │               │          └ array([[  2,   2],
    │   │               │                   [631, 631]])
    │   │               └ array([[[191, 191, 191],
    │   │                         [170, 170, 170],
    │   │                         [164, 164, 164],
    │   │                         ...,
    │   │                         [220, 220, 220],
    │   │                         [214...
    │   └ <built-in function imshow>
    └ <module 'cv2' from 'C:\\pycharm\\pythonProject\\ComparsionProject\\venv\\lib\\site-packages\\cv2\\__init__.py'>

cv2.error: OpenCV(4.8.0) D:\a\opencv-python\opencv-python\opencv\modules\highgui\src\window.cpp:971: error: (-215:Assertion failed) size.width>0 && size.height>0 in function 'cv::imshow'

2023-09-20 15:59:22.523 | ERROR    | __main__:screen_shot:1150 - An error has been caught in function 'screen_shot', process 'MainProcess' (13152), thread 'MainThread' (9940):
Traceback (most recent call last):

  File "C:\pycharm\pythonProject\ComparsionProject\BasicDemo\tktest.py", line 1227, in <module>
    window.mainloop()
    │      └ <function Misc.mainloop at 0x000001EE11F1F940>
    └ <tkinter.Tk object .>

  File "C:\python3.9.10\lib\tkinter\__init__.py", line 1429, in mainloop
    self.tk.mainloop(n)
    │    │  │        └ 0
    │    │  └ <method 'mainloop' of '_tkinter.tkapp' objects>
    │    └ <_tkinter.tkapp object at 0x000001EE2EA35D30>
    └ <tkinter.Tk object .>

  File "C:\python3.9.10\lib\tkinter\__init__.py", line 1892, in __call__
    return self.func(*args)
           │    │     └ ()
           │    └ <function screen_shot at 0x000001EE31AF6790>
           └ <tkinter.CallWrapper object at 0x000001EE31AF5A60>

> File "C:\pycharm\pythonProject\ComparsionProject\BasicDemo\tktest.py", line 1150, in screen_shot
    cv2.waitKey(0)
    │   └ <built-in function waitKey>
    └ <module 'cv2' from 'C:\\pycharm\\pythonProject\\ComparsionProject\\venv\\lib\\site-packages\\cv2\\__init__.py'>

  File "C:\pycharm\pythonProject\ComparsionProject\BasicDemo\tktest.py", line 1136, in on_mouse
    cv2.imshow('image', screen_img[cut_Pos[1][0]:cut_Pos[1][1], cut_Pos[0][0]:cut_Pos[0][1]])
    │   │               │          │             │              │             └ array([[685, 685],
    │   │               │          │             │              │                      [283, 283]])
    │   │               │          │             │              └ array([[685, 685],
    │   │               │          │             │                       [283, 283]])
    │   │               │          │             └ array([[685, 685],
    │   │               │          │                      [283, 283]])
    │   │               │          └ array([[685, 685],
    │   │               │                   [283, 283]])
    │   │               └ array([[[191, 191, 191],
    │   │                         [170, 170, 170],
    │   │                         [164, 164, 164],
    │   │                         ...,
    │   │                         [220, 220, 220],
    │   │                         [214...
    │   └ <built-in function imshow>
    └ <module 'cv2' from 'C:\\pycharm\\pythonProject\\ComparsionProject\\venv\\lib\\site-packages\\cv2\\__init__.py'>

cv2.error: OpenCV(4.8.0) D:\a\opencv-python\opencv-python\opencv\modules\highgui\src\window.cpp:971: error: (-215:Assertion failed) size.width>0 && size.height>0 in function 'cv::imshow'

